<?xml version="1.0"?>
<robot xmlns:xacro="http://www.ros.org/wiki/xacro" name="alkimia_door">

	<xacro:property name="pi" value="3.1415926535897931" />
	<xacro:property name="coupleFins" value="true" />

	<!-- Profile model -->

	<xacro:macro name="profile" params="parent name position orientation">

		<joint name="${name}_joint" type="fixed">
			<origin xyz="${position}" rpy="${orientation}" />
			<parent link="${parent}"/>
			<child link="${name}"/>
			<axis xyz="1 0 0" />
			<limit lower="${0*pi/180}" upper="${90*pi/180}" effort="60" velocity="10"/>
			<dynamics damping="1.0" friction="10.0"/>
		</joint>

		<link name="${name}">
			<inertial>
				<origin xyz="0 0 -0.1" rpy="0 0 0"/>
				<mass value="50.0"/>
				<inertia
				ixx="1.0" ixy="0.0" ixz="0.0"
				iyy="1.0" iyz="0.0"
				izz="1.0"/>
			</inertial>
			<visual>
				<origin xyz="0 0 0" rpy="0.0 0 0"/>
				<geometry>
					<mesh filename="package://alkimia_door/urdf/meshes/roof.stl" scale=" .001 .001 .001" />
					<!-- box size="0.2 0.2 5.1"/ -->
				</geometry>
				<material name="Gray">
					<color rgba="0.5 0.5 0.5 1.0"/>
				</material>
			</visual>
			<collision>
				<origin xyz="-0.1 -4 -0.1" rpy="0.0 0 0"/>
				<geometry>
					<box size="0.2 8 0.2"/>
				</geometry>
			</collision>
		</link>
	</xacro:macro>

	<!-- FIN model -->
	<xacro:macro name="fin" params="parent name position orientation">

		<!-- TOP FIN -->
		<joint name="${name}_top_joint" type="revolute">
			<origin xyz="${position}" rpy="${orientation}" />
			<parent link="${parent}"/>
			<child link="${name}_top_fin"/>
			<axis xyz="1 0 0" />
			<limit lower="${0*pi/180}" upper="${90*pi/180}" effort="60" velocity="10"/>
			<dynamics damping="1.0" friction="10.0"/>
		</joint>

		<link name="${name}_top_fin">
			<inertial>
				<origin xyz="-0.1 -0.55 0.01" rpy="0 0 0"/>
				<mass value="2.0"/>
				<inertia
				ixx="2.6" ixy="0.0" ixz="0.0"
				iyy="0.06" iyz="0.0"
				izz="2.6"/>
			</inertial>
			<visual>
				<origin xyz="0 0 0" rpy="0 0 0" />
				<geometry>
					<mesh filename="package://alkimia_door/urdf/meshes/top_fin.stl" scale=" .001 .001 .001" />
					<!-- box size="1.0 0.01 0.3"/ -->
				</geometry>
				<material name="Brown">
					<color rgba="0.545 0.27 0.07 1.0"/>
				</material>
			</visual>
			<collision>
				<origin xyz="-0.1 -0.55 0.01" rpy="0 0 0" />
				<geometry>
					<!-- mesh filename="package://alkimia_door/urdf/meshes/top_fin.stl" scale=" .001 .001 .001" / -->
					<box size="0.2 1.1 0.02"/>
				</geometry>
			</collision>
		</link>

		<!-- BOTTOM FIN -->
		<joint name="${name}_bottom_joint" type="revolute">
			<origin xyz="0.0 -1.11 0.0" rpy="-1.57 0 -1.57" />
			<parent link="${name}_top_fin"/>
			<child link="${name}_bottom_fin"/>
			<axis xyz="0 0 -1" />
			<limit lower="${0*pi/180}" upper="${180*pi/180}" effort="60" velocity="10"/>
			<dynamics damping="0.5" friction="5.0"/>
		</joint>

		<link name="${name}_bottom_fin">
			<inertial>
				<origin xyz="0.35 -0.01 -0.1" rpy="0 0 0"/>
				<mass value="1.5"/>
				<inertia
				ixx="0.03" ixy="0.0" ixz="0.0"
				iyy="1.3" iyz="0.0"
				izz="1.3"/>
			</inertial>
			<visual>
				<origin xyz="0.07 0.12 -0.017" rpy="0 0 0" />
				<geometry>
					<mesh filename="package://alkimia_door/urdf/meshes/bottom_fin.stl" scale=" .001 .001 .001" />
					<!-- box size="1.0 0.01 0.3"/ -->
				</geometry>
				<material name="Brown">
					<color rgba="0.545 0.27 0.07 1.0"/>
				</material>
			</visual>
			<collision>
				<origin xyz="0.65 -0.01 -0.1" rpy="0 0 0" />
				<geometry>
					<!-- mesh filename="package://alkimia_door/urdf/meshes/bottom_fin.stl" scale=" .001 .001 .001" / -->
					<box size="1.3 0.02 0.2"/>
				</geometry>
			</collision>
		</link>

		<transmission name="${name}_top_fin_trans">
			<type>transmission_interface/SimpleTransmission</type>
			<joint name="${name}_top_joint">
				<hardwareInterface>EffortJointInterface</hardwareInterface>
			</joint>
			<actuator name="${name}_top_fin_motor">
				<mechanicalReduction>1</mechanicalReduction>
			</actuator>
		</transmission>

		<transmission name="${name}_bottom_fin_trans">
			<type>transmission_interface/SimpleTransmission</type>
			<joint name="${name}_bottom_joint">
				<hardwareInterface>PositionJointInterface</hardwareInterface>
			</joint>
			<actuator name="${name}_top_fin_motor">
				<mechanicalReduction>-2</mechanicalReduction>
			</actuator>
		</transmission>

	</xacro:macro>

	<link name="world"/>

    <xacro:profile parent="world" name="Iprofile1" position="0.0 0.0 0.0" orientation="0.0 0.0 0.0" />
	<xacro:fin parent="Iprofile1" name="fin1" position="0.11 -0.13 -0.2" orientation="0 1.57 1.57" />

    <xacro:profile parent="world" name="Iprofile2" position="0.0 0.0 0.3" orientation="0.0 0.0 0.0" />
	<xacro:fin parent="Iprofile2" name="fin2" position="0.11 -0.13 -0.2" orientation="0 1.57 1.57" />

    <xacro:profile parent="world" name="Iprofile3" position="0.0 0.0 0.6" orientation="0.0 0.0 0.0" />
	<xacro:fin parent="Iprofile3" name="fin3" position="0.11 -0.13 -0.2" orientation="0 1.57 1.57" />

    <xacro:profile parent="world" name="Iprofile4" position="0.0 0.0 0.9" orientation="0.0 0.0 0.0" />
	<xacro:fin parent="Iprofile4" name="fin4" position="0.11 -0.13 -0.2" orientation="0 1.57 1.57" />

    <xacro:profile parent="world" name="Iprofile5" position="0.0 0.0 1.2" orientation="0.0 0.0 0.0" />
	<xacro:fin parent="Iprofile5" name="fin5" position="0.11 -0.13 -0.2" orientation="0 1.57 1.57" />

    <xacro:profile parent="world" name="Iprofile6" position="0.0 0.0 1.5" orientation="0.0 0.0 0.0" />
	<xacro:fin parent="Iprofile6" name="fin6" position="0.11 -0.13 -0.2" orientation="0 1.57 1.57" />

    <xacro:profile parent="world" name="Iprofile7" position="0.0 0.0 1.8" orientation="0.0 0.0 0.0" />
	<xacro:fin parent="Iprofile7" name="fin7" position="0.11 -0.13 -0.2" orientation="0 1.57 1.57" />

	<!-- <xacro:fin parent="Iprofile" name="fin3" position="0 0 0.6" orientation="0 0 0" isCoupled="${coupleFins}" ratio="2"/>

	<xacro:fin parent="Iprofile" name="fin4" position="0 0 0.9" orientation="0 0 0" isCoupled="${coupleFins}" ratio="2"/>

	<xacro:fin parent="Iprofile" name="fin5" position="0 0 1.2" orientation="0 0 0" isCoupled="${coupleFins}" ratio="2"/>

	<xacro:fin parent="Iprofile" name="fin6" position="0 0 1.5" orientation="0 0 0" isCoupled="${coupleFins}" ratio="2"/>

	<xacro:fin parent="Iprofile" name="fin7" position="0 0 1.8" orientation="0 0 0" isCoupled="${coupleFins}" ratio="2"/>

	<xacro:fin parent="Iprofile" name="fin8" position="0 0 2.1" orientation="0 0 0" isCoupled="${coupleFins}" ratio="2"/>

	<xacro:fin parent="Iprofile" name="fin9" position="0 0 2.4" orientation="0 0 0" isCoupled="${coupleFins}" ratio="2"/>

	<xacro:fin parent="Iprofile" name="fin10" position="0 0 2.7" orientation="0 0 0" isCoupled="${coupleFins}" ratio="2"/>

	<xacro:fin parent="Iprofile" name="fin11" position="0 0 3.0" orientation="0 0 0" isCoupled="${coupleFins}" ratio="2"/>

	<xacro:fin parent="Iprofile" name="fin12" position="0 0 3.3" orientation="0 0 0" isCoupled="${coupleFins}" ratio="2"/>

	<xacro:fin parent="Iprofile" name="fin13" position="0 0 3.6" orientation="0 0 0" isCoupled="${coupleFins}" ratio="2"/>

	<xacro:fin parent="Iprofile" name="fin14" position="0 0 3.9" orientation="0 0 0" isCoupled="${coupleFins}" ratio="2"/>

	<xacro:fin parent="Iprofile" name="fin15" position="0 0 4.2" orientation="0 0 0" isCoupled="${coupleFins}" ratio="2"/>

	<xacro:fin parent="Iprofile" name="fin16" position="0 0 4.5" orientation="0 0 0" isCoupled="${coupleFins}" ratio="2"/>

	<xacro:fin parent="Iprofile" name="fin17" position="0 0 4.8" orientation="0 0 0" isCoupled="${coupleFins}" ratio="2"/> -->

	<gazebo>
		<plugin name="alkimia_plugins" filename="libalkimia_plugins.so">
			<robotNamespace>alkimia_door</robotNamespace>
			<master1>fin1</master1>
			<couplingStiffness>150</couplingStiffness>
		</plugin>
	</gazebo>

</robot>